<?xml version="1.0" encoding="utf-8"?>
<!-- This URDF was automatically created by SolidWorks to URDF Exporter! Originally created by Stephen Brawner (brawner@gmail.com) 
     Commit Version: 1.5.1-0-g916b5db  Build Version: 1.5.7152.31018
     For more information, please see http://wiki.ros.org/sw_urdf_exporter -->
<robot
  name="leap_vtol_mk3">
  <link
    name="base_link">
    <inertial>
      <origin
        xyz="-5.6365E-05 0.12885 -0.50375"
        rpy="0 0 0" />
      <mass
        value="5260.29" />
      <inertia
        ixx="514787000000"
        ixy="76545660"
        ixz="-152720"
        iyy="1158280000000"
        iyz="-34080623440"
        izz="684276000000" />
    </inertial>
    <visual>
      <origin
        xyz="0 0 0"
        rpy="0 0 0" />
      <geometry>
        <mesh
          filename="package://leap_vtol_mk3/meshes/base_link.STL" />
      </geometry>
      <material
        name="">
        <color
          rgba="0.79216 0.81961 0.93333 1" />
      </material>
    </visual>
    <collision>
      <origin
        xyz="0 0 0"
        rpy="0 0 0" />
      <geometry>
        <mesh
          filename="package://leap_vtol_mk3/meshes/base_link.STL" />
      </geometry>
    </collision>
  </link>
<!-- --------------------------------------------------------------------------- -->
  <link name='leap_vtol_mk3/imu_link'>
    <pose>0 0 0 0 0 0</pose>
    <inertial>
      <pose>0 0 0 0 0 0</pose>
      <mass>0.015</mass>
      <inertia>
        <ixx>1e-05</ixx>
        <ixy>0</ixy>
        <ixz>0</ixz>
        <iyy>1e-05</iyy>
        <iyz>0</iyz>
        <izz>1e-05</izz>
      </inertia>
    </inertial>
  </link>
  <joint name='leap_vtol_mk3/imu_joint' type='revolute'>
    <child>leap_vtol_mk3/imu_link</child>
    <parent>base_link</parent>
    <axis>
      <xyz>1 0 0</xyz>
      <limit>
        <lower>0</lower>
        <upper>0</upper>
        <effort>0</effort>
        <velocity>0</velocity>
      </limit>
      <dynamics>
        <spring_reference>0</spring_reference>
        <spring_stiffness>0</spring_stiffness>
      </dynamics>
      <use_parent_model_frame>1</use_parent_model_frame>
    </axis>
  </joint>
<!-- --------------------------------------------------------------------------- -->
  <link
    name="motor_1">
    <inertial>
      <origin
        xyz="1.8619E-08 0.0054745 -6.6772E-07"
        rpy="0 0 0" />
      <mass
        value="0.0048824" />
      <inertia
        ixx="2.0132E-05"
        ixy="-1.4938E-13"
        ixz="9.2457E-07"
        iyy="2.0296E-05"
        iyz="-2.8276E-13"
        izz="1.9619E-07" />
    </inertial>
    <visual>
      <origin
        xyz="0 0 0"
        rpy="0 0 0" />
      <geometry>
        <mesh
          filename="package://leap_vtol_mk3/meshes/motor_1.STL" />
      </geometry>
      <material
        name="">
        <color
          rgba="0.49412 0.49412 0.49412 1" />
      </material>
    </visual>
    <collision>
      <origin
        xyz="0 0 0"
        rpy="0 0 0" />
      <geometry>
        <mesh
          filename="package://leap_vtol_mk3/meshes/motor_1.STL" />
      </geometry>
    </collision>
  </link>
  <joint
    name="motor_1_joint"
    type="revolute">
    <origin
      xyz="-0.35935 0.28363 0.23968"
      rpy="1.5708 0 1.7806" />
    <parent
      link="base_link" />
    <child
      link="motor_1" />
    <axis
      xyz="0 1 0" />
    <limit
      lower="-1e+16"
      upper="1e+16"
      effort="0"
      velocity="0" />
  </joint>
<!-- --------------------------------------------------------------------------- -->
  <link
    name="motor_2">
    <inertial>
      <origin
        xyz="3.6051E-10 0.0054745 2.6263E-09"
        rpy="0 0 0" />
      <mass
        value="0.0048824" />
      <inertia
        ixx="2.0132E-05"
        ixy="6.4409E-15"
        ixz="9.2458E-07"
        iyy="2.0296E-05"
        iyz="4.7163E-14"
        izz="1.9619E-07" />
    </inertial>
    <visual>
      <origin
        xyz="0 0 0"
        rpy="0 0 0" />
      <geometry>
        <mesh
          filename="package://leap_vtol_mk3/meshes/motor_2.STL" />
      </geometry>
      <material
        name="">
        <color
          rgba="0.49412 0.49412 0.49412 1" />
      </material>
    </visual>
    <collision>
      <origin
        xyz="0 0 0"
        rpy="0 0 0" />
      <geometry>
        <mesh
          filename="package://leap_vtol_mk3/meshes/motor_2.STL" />
      </geometry>
    </collision>
  </link>
  <joint
    name="motor_2_joint"
    type="revolute">
    <origin
      xyz="0.35935 0.28363 0.23968"
      rpy="1.5708 0 2.6481" />
    <parent
      link="base_link" />
    <child
      link="motor_2" />
    <axis
      xyz="0 1 0" />
    <limit
      lower="-1e+16"
      upper="1e+16"
      effort="0"
      velocity="0" />
  </joint>
<!-- --------------------------------------------------------------------------- -->
  <link
    name="motor_3">
    <inertial>
      <origin
        xyz="-1.8643E-08 0.0054745 6.6754E-07"
        rpy="0 0 0" />
      <mass
        value="0.0048824" />
      <inertia
        ixx="2.0132E-05"
        ixy="1.4908E-13"
        ixz="9.2465E-07"
        iyy="2.0296E-05"
        iyz="2.8112E-13"
        izz="1.962E-07" />
    </inertial>
    <visual>
      <origin
        xyz="0 0 0"
        rpy="0 0 0" />
      <geometry>
        <mesh
          filename="package://leap_vtol_mk3/meshes/motor_3.STL" />
      </geometry>
      <material
        name="">
        <color
          rgba="0.49412 0.49412 0.49412 1" />
      </material>
    </visual>
    <collision>
      <origin
        xyz="0 0 0"
        rpy="0 0 0" />
      <geometry>
        <mesh
          filename="package://leap_vtol_mk3/meshes/motor_3.STL" />
      </geometry>
    </collision>
  </link>
  <joint
    name="motor_3_joint"
    type="revolute">
    <origin
      xyz="0.35935 0.83392 0.23968"
      rpy="1.5708 0 2.7896" />
    <parent
      link="base_link" />
    <child
      link="motor_3" />
    <axis
      xyz="0 1 0" />
    <limit
      lower="-1e+16"
      upper="1e+16"
      effort="0"
      velocity="0" />
  </joint>
<!-- --------------------------------------------------------------------------- -->
  <link
    name="motor_4">
    <inertial>
      <origin
        xyz="6.4855E-08 0.0054745 6.5904E-08"
        rpy="0 0 0" />
      <mass
        value="0.0048824" />
      <inertia
        ixx="2.0132E-05"
        ixy="4.254E-13"
        ixz="9.2462E-07"
        iyy="2.0296E-05"
        iyz="-1.6876E-12"
        izz="1.962E-07" />
    </inertial>
    <visual>
      <origin
        xyz="0 0 0"
        rpy="0 0 0" />
      <geometry>
        <mesh
          filename="package://leap_vtol_mk3/meshes/motor_4.STL" />
      </geometry>
      <material
        name="">
        <color
          rgba="0.49412 0.49412 0.49412 1" />
      </material>
    </visual>
    <collision>
      <origin
        xyz="0 0 0"
        rpy="0 0 0" />
      <geometry>
        <mesh
          filename="package://leap_vtol_mk3/meshes/motor_4.STL" />
      </geometry>
    </collision>
  </link>
  <joint
    name="motor_4_joint"
    type="revolute">
    <origin
      xyz="-0.35935 0.83392 0.23968"
      rpy="1.5708 0 -2.2362" />
    <parent
      link="base_link" />
    <child
      link="motor_4" />
    <axis
      xyz="0 1 0" />
    <limit
      lower="-1e+16"
      upper="1e+16"
      effort="0"
      velocity="0" />
  </joint>
<!-- --------------------------------------------------------------------------- -->
  <link
    name="motor_5">
    <inertial>
      <origin
        xyz="-2.3972E-11 0.0054745 -1.7397E-10"
        rpy="0 0 0" />
      <mass
        value="0.0048823" />
      <inertia
        ixx="2.0132E-05"
        ixy="-3.0781E-16"
        ixz="9.2456E-07"
        iyy="2.0295E-05"
        iyz="-1.6139E-15"
        izz="1.9619E-07" />
    </inertial>
    <visual>
      <origin
        xyz="0 0 0"
        rpy="0 0 0" />
      <geometry>
        <mesh
          filename="package://leap_vtol_mk3/meshes/motor_5.STL" />
      </geometry>
      <material
        name="">
        <color
          rgba="0.49412 0.49412 0.49412 1" />
      </material>
    </visual>
    <collision>
      <origin
        xyz="0 0 0"
        rpy="0 0 0" />
      <geometry>
        <mesh
          filename="package://leap_vtol_mk3/meshes/motor_5.STL" />
      </geometry>
    </collision>
  </link>
  <joint
    name="motor_5_joint"
    type="revolute">
    <origin
      xyz="0.67935 0.28363 0.23968"
      rpy="1.5708 0 2.7896" />
    <parent
      link="base_link" />
    <child
      link="motor_5" />
    <axis
      xyz="0 1 0" />
    <limit
      lower="-1e+16"
      upper="1e+16"
      effort="0"
      velocity="0" />
  </joint>
<!-- --------------------------------------------------------------------------- -->
  <link
    name="motor_6">
    <inertial>
      <origin
        xyz="-1.0394E-07 0.0054745 1.2568E-06"
        rpy="0 0 0" />
      <mass
        value="0.0048824" />
      <inertia
        ixx="2.0132E-05"
        ixy="-1.6107E-13"
        ixz="9.2462E-07"
        iyy="2.0296E-05"
        iyz="2.0205E-12"
        izz="1.962E-07" />
    </inertial>
    <visual>
      <origin
        xyz="0 0 0"
        rpy="0 0 0" />
      <geometry>
        <mesh
          filename="package://leap_vtol_mk3/meshes/motor_6.STL" />
      </geometry>
      <material
        name="">
        <color
          rgba="0.49412 0.49412 0.49412 1" />
      </material>
    </visual>
    <collision>
      <origin
        xyz="0 0 0"
        rpy="0 0 0" />
      <geometry>
        <mesh
          filename="package://leap_vtol_mk3/meshes/motor_6.STL" />
      </geometry>
    </collision>
  </link>
  <joint
    name="motor_6_joint"
    type="revolute">
    <origin
      xyz="-0.67985 0.28363 0.23968"
      rpy="1.5708 0 -2.3392" />
    <parent
      link="base_link" />
    <child
      link="motor_6" />
    <axis
      xyz="0 1 0" />
    <limit
      lower="-1e+16"
      upper="1e+16"
      effort="0"
      velocity="0" />
  </joint>
<!-- --------------------------------------------------------------------------- -->
  <link
    name="motor_7">
    <inertial>
      <origin
        xyz="-8.4037E-08 0.0054745 5.9805E-07"
        rpy="0 0 0" />
      <mass
        value="0.0048825" />
      <inertia
        ixx="2.0132E-05"
        ixy="-2.8647E-13"
        ixz="9.2462E-07"
        iyy="2.0296E-05"
        iyz="2.0534E-12"
        izz="1.962E-07" />
    </inertial>
    <visual>
      <origin
        xyz="0 0 0"
        rpy="0 0 0" />
      <geometry>
        <mesh
          filename="package://leap_vtol_mk3/meshes/motor_7.STL" />
      </geometry>
      <material
        name="">
        <color
          rgba="0.49412 0.49412 0.49412 1" />
      </material>
    </visual>
    <collision>
      <origin
        xyz="0 0 0"
        rpy="0 0 0" />
      <geometry>
        <mesh
          filename="package://leap_vtol_mk3/meshes/motor_7.STL" />
      </geometry>
    </collision>
  </link>
  <joint
    name="motor_7_joint"
    type="revolute">
    <origin
      xyz="-0.67985 0.83392 0.23968"
      rpy="1.5708 0 1.8808" />
    <parent
      link="base_link" />
    <child
      link="motor_7" />
    <axis
      xyz="0 1 0" />
    <limit
      lower="-1e+16"
      upper="1e+16"
      effort="0"
      velocity="0" />
  </joint>
<!-- --------------------------------------------------------------------------- -->
  <link
    name="motor_8">
    <inertial>
      <origin
        xyz="3.84480225434913E-10 0.00547447836547874 2.80021761334126E-09"
        rpy="0 0 0" />
      <mass
        value="0.00488248531425739" />
      <inertia
        ixx="2.01327899926299E-05"
        ixy="6.74865407710483E-15"
        ixz="9.24660696074812E-07"
        iyy="2.02966094872409E-05"
        iyz="4.87763759161582E-14"
        izz="1.96200454476914E-07" />
    </inertial>
    <visual>
      <origin
        xyz="0 0 0"
        rpy="0 0 0" />
      <geometry>
        <mesh
          filename="package://leap_vtol_mk3/meshes/motor_8.STL" />
      </geometry>
      <material
        name="">
        <color
          rgba="0.494117647058824 0.494117647058824 0.494117647058824 1" />
      </material>
    </visual>
    <collision>
      <origin
        xyz="0 0 0"
        rpy="0 0 0" />
      <geometry>
        <mesh
          filename="package://leap_vtol_mk3/meshes/motor_8.STL" />
      </geometry>
    </collision>
  </link>
  <joint
    name="motor_8_joint"
    type="revolute">
    <origin
      xyz="0.67935 0.83392 0.23968"
      rpy="1.5708 0 2.7896" />
    <parent
      link="base_link" />
    <child
      link="motor_8" />
    <axis
      xyz="0 1 0" />
    <limit
      lower="-1e+16"
      upper="1e+16"
      effort="0"
      velocity="0" />
  </joint>
<!-- --------------------------------------------------------------------------- -->
  <link
    name="cruise_motor">
    <inertial>
      <origin
        xyz="3.6051E-10 -0.0054311 2.6263E-09"
        rpy="0 0 0" />
      <mass
        value="0.0048824" />
      <inertia
        ixx="2.0132E-05"
        ixy="6.4408E-15"
        ixz="9.2458E-07"
        iyy="2.0296E-05"
        iyz="4.7163E-14"
        izz="1.9619E-07" />
    </inertial>
    <visual>
      <origin
        xyz="0 0 0"
        rpy="0 0 0" />
      <geometry>
        <mesh
          filename="package://leap_vtol_mk3/meshes/cruise_motor.STL" />
      </geometry>
      <material
        name="">
        <color
          rgba="0.49412 0.49412 0.49412 1" />
      </material>
    </visual>
    <collision>
      <origin
        xyz="0 0 0"
        rpy="0 0 0" />
      <geometry>
        <mesh
          filename="package://leap_vtol_mk3/meshes/cruise_motor.STL" />
      </geometry>
    </collision>
  </link>
  <joint
    name="cruise_motor_joint"
    type="revolute">
    <origin
      xyz="0 1.4624 0.1585"
      rpy="3.1416 -0.97948 0" />
    <parent
      link="base_link" />
    <child
      link="cruise_motor" />
    <axis
      xyz="0 1 0" />
    <limit
      lower="-1e+16"
      upper="1e+16"
      effort="0"
      velocity="0" />
  </joint>
<!-- --------------------------------------------------------------------------- -->
  <link
    name="aileron_right">
    <inertial>
      <origin
        xyz="0.000359429626028307 -0.00792280043359631 -0.25807892576358"
        rpy="0 0 0" />
      <mass
        value="0.000477234933527631" />
      <inertia
        ixx="2.19976884447218E-09"
        ixy="3.40084968517089E-09"
        ixz="5.86757159837328E-19"
        iyy="2.05168737623326E-08"
        iyz="-7.70638457316328E-19"
        izz="2.23984858895856E-08" />
    </inertial>
    <visual>
      <origin
        xyz="0 0 0"
        rpy="0 0 0" />
      <geometry>
        <mesh
          filename="package://leap_vtol_mk3/meshes/aileron_right.STL" />
      </geometry>
      <material
        name="">
        <color
          rgba="0.772549019607843 0.752941176470588 0.733333333333333 1" />
      </material>
    </visual>
    <collision>
      <origin
        xyz="0 0 0"
        rpy="0 0 0" />
      <geometry>
        <mesh
          filename="package://leap_vtol_mk3/meshes/aileron_right.STL" />
      </geometry>
    </collision>
  </link>
  <joint
    name="aileron_right_joint"
    type="revolute">
    <origin
      xyz="-0.45216 0.65442 0.20642"
      rpy="1.5699 0.015027 1.5726" />
    <parent
      link="base_link" />
    <child
      link="aileron_right" />
    <axis
      xyz="0.057465 0 0.99835" />
    <limit
      lower="0"
      upper="0"
      effort="0"
      velocity="0" />
  </joint>
<!-- --------------------------------------------------------------------------- -->
  <link
    name="aileron_left">
    <inertial>
      <origin
        xyz="9.8636E-05 -0.0079228 0.26261"
        rpy="0 0 0" />
      <mass
        value="0.00047723" />
      <inertia
        ixx="2.1998E-09"
        ixy="3.4008E-09"
        ixz="-4.0722E-19"
        iyy="2.0517E-08"
        iyz="5.1609E-19"
        izz="2.2398E-08" />
    </inertial>
    <visual>
      <origin
        xyz="0 0 0"
        rpy="0 0 0" />
      <geometry>
        <mesh
          filename="package://leap_vtol_mk3/meshes/aileron_left.STL" />
      </geometry>
      <material
        name="">
        <color
          rgba="0.77255 0.75294 0.73333 1" />
      </material>
    </visual>
    <collision>
      <origin
        xyz="0 0 0"
        rpy="0 0 0" />
      <geometry>
        <mesh
          filename="package://leap_vtol_mk3/meshes/aileron_left.STL" />
      </geometry>
    </collision>
  </link>
  <joint
    name="aileron_left_joint"
    type="revolute">
    <origin
      xyz="0.44556 0.65481 0.20642"
      rpy="1.5808 0.17275 1.5699" />
    <parent
      link="base_link" />
    <child
      link="aileron_left" />
    <axis
      xyz="0.057465 0 -0.99835" />
    <limit
      lower="0"
      upper="0"
      effort="0"
      velocity="0" />
  </joint>
<!-- --------------------------------------------------------------------------- -->
  <link
    name="elevator">
    <inertial>
      <origin
        xyz="0.0204328544188923 -0.00197488435501691 5.86160068176164E-15"
        rpy="0 0 0" />
      <mass
        value="0.0473579286571473" />
      <inertia
        ixx="0.000345850971992126"
        ixy="4.17697374302898E-07"
        ixz="-2.75413791250375E-20"
        iyy="0.000352096502918169"
        iyz="1.30635602608801E-19"
        izz="6.3329578705762E-06" />
    </inertial>
    <visual>
      <origin
        xyz="0 0 0"
        rpy="0 0 0" />
      <geometry>
        <mesh
          filename="package://leap_vtol_mk3/meshes/elevator.STL" />
      </geometry>
      <material
        name="">
        <color
          rgba="0.580392156862745 0.886274509803922 0.862745098039216 1" />
      </material>
    </visual>
    <collision>
      <origin
        xyz="0 0 0"
        rpy="0 0 0" />
      <geometry>
        <mesh
          filename="package://leap_vtol_mk3/meshes/elevator.STL" />
      </geometry>
    </collision>
  </link>
  <joint
    name="elevator_joint"
    type="revolute">
    <origin
      xyz="0 1.3739 0.17"
      rpy="1.5708 0.040426 1.5708" />
    <parent
      link="base_link" />
    <child
      link="elevator" />
    <axis
      xyz="0 0 1" />
    <limit
      lower="0"
      upper="0"
      effort="0"
      velocity="0" />
  </joint>
<!-- --------------------------------------------------------------------------- -->
  <link
    name="rudder">
    <inertial>
      <origin
        xyz="0.0039829653811192 0.117786619293133 -0.000428313690817694"
        rpy="0 0 0" />
      <mass
        value="0.00519552270790543" />
      <inertia
        ixx="2.32455549928391E-05"
        ixy="1.25670300101702E-08"
        ixz="1.79671302680659E-08"
        iyy="5.69043771637136E-08"
        iyz="-5.09533985704648E-09"
        izz="2.32380324433504E-05" />
    </inertial>
    <visual>
      <origin
        xyz="0 0 0"
        rpy="0 0 0" />
      <geometry>
        <mesh
          filename="package://leap_vtol_mk3/meshes/rudder.STL" />
      </geometry>
      <material
        name="">
        <color
          rgba="0.580392156862745 0.886274509803922 0.862745098039216 1" />
      </material>
    </visual>
    <collision>
      <origin
        xyz="0 0 0"
        rpy="0 0 0" />
      <geometry>
        <mesh
          filename="package://leap_vtol_mk3/meshes/rudder.STL" />
      </geometry>
    </collision>
  </link>
  <joint
    name="rudder_joint"
    type="revolute">
    <origin
      xyz="0 1.3287 0.17556"
      rpy="1.5708 0.00041301 1.6252" />
    <parent
      link="base_link" />
    <child
      link="rudder" />
    <axis
      xyz="0.00041301 -1 0" />
    <limit
      lower="0"
      upper="0"
      effort="0"
      velocity="0" />
  </joint>

<!-- --------------------------------------------------------------------------- -->

  <plugin name='front_right_root_motor_model' filename='libgazebo_motor_model.so'>
    <robotNamespace></robotNamespace>
    <jointName>motor_1_joint</jointName>
    <linkName>motor_1</linkName>
    <turningDirection>ccw</turningDirection>
    <timeConstantUp>0.0125</timeConstantUp>
    <timeConstantDown>0.025</timeConstantDown>
    <maxRotVelocity>1500</maxRotVelocity>
    <motorConstant>8.54858e-06</motorConstant>
    <momentConstant>0.06</momentConstant>
    <commandSubTopic>/gazebo/command/motor_speed</commandSubTopic>
    <motorNumber>1</motorNumber>
    <rotorDragCoefficient>0.000806428</rotorDragCoefficient>
    <rollingMomentCoefficient>1e-06</rollingMomentCoefficient>
    <motorSpeedPubTopic>/motor_speed/1</motorSpeedPubTopic>
    <rotorVelocitySlowdownSim>20</rotorVelocitySlowdownSim>
  </plugin>

  <plugin name='front_left_root_motor_model' filename='libgazebo_motor_model.so'>
    <robotNamespace></robotNamespace>
    <jointName>motor_2_joint</jointName>
    <linkName>motor_2</linkName>
    <turningDirection>cw</turningDirection>
    <timeConstantUp>0.0125</timeConstantUp>
    <timeConstantDown>0.025</timeConstantDown>
    <maxRotVelocity>1500</maxRotVelocity>
    <motorConstant>8.54858e-06</motorConstant>
    <momentConstant>0.06</momentConstant>
    <commandSubTopic>/gazebo/command/motor_speed</commandSubTopic>
    <motorNumber>2</motorNumber>
    <rotorDragCoefficient>0.000806428</rotorDragCoefficient>
    <rollingMomentCoefficient>1e-06</rollingMomentCoefficient>
    <motorSpeedPubTopic>/motor_speed/2</motorSpeedPubTopic>
    <rotorVelocitySlowdownSim>20</rotorVelocitySlowdownSim>
  </plugin>

  <plugin name='back_left_root_motor_model' filename='libgazebo_motor_model.so'>
    <robotNamespace></robotNamespace>
    <jointName>motor_3_joint</jointName>
    <linkName>motor_3</linkName>
    <turningDirection>ccw</turningDirection>
    <timeConstantUp>0.0125</timeConstantUp>
    <timeConstantDown>0.025</timeConstantDown>
    <maxRotVelocity>1500</maxRotVelocity>
    <motorConstant>8.54858e-06</motorConstant>
    <momentConstant>0.06</momentConstant>
    <commandSubTopic>/gazebo/command/motor_speed</commandSubTopic>
    <motorNumber>3</motorNumber>
    <rotorDragCoefficient>0.000806428</rotorDragCoefficient>
    <rollingMomentCoefficient>1e-06</rollingMomentCoefficient>
    <motorSpeedPubTopic>/motor_speed/3</motorSpeedPubTopic>
    <rotorVelocitySlowdownSim>20</rotorVelocitySlowdownSim>
  </plugin>

  <plugin name='back_right_root_motor_model' filename='libgazebo_motor_model.so'>
    <robotNamespace></robotNamespace>
    <jointName>motor_4_joint</jointName>
    <linkName>motor_4</linkName>
    <turningDirection>cw</turningDirection>
    <timeConstantUp>0.0125</timeConstantUp>
    <timeConstantDown>0.025</timeConstantDown>
    <maxRotVelocity>1500</maxRotVelocity>
    <motorConstant>8.54858e-06</motorConstant>
    <momentConstant>0.06</momentConstant>
    <commandSubTopic>/gazebo/command/motor_speed</commandSubTopic>
    <motorNumber>4</motorNumber>
    <rotorDragCoefficient>0.000806428</rotorDragCoefficient>
    <rollingMomentCoefficient>1e-06</rollingMomentCoefficient>
    <motorSpeedPubTopic>/motor_speed/4</motorSpeedPubTopic>
    <rotorVelocitySlowdownSim>20</rotorVelocitySlowdownSim>
  </plugin>

  <plugin name='front_left_tip_motor_model' filename='libgazebo_motor_model.so'>
    <robotNamespace></robotNamespace>
    <jointName>motor_5_joint</jointName>
    <linkName>motor_5</linkName>
    <turningDirection>ccw</turningDirection>
    <timeConstantUp>0.0125</timeConstantUp>
    <timeConstantDown>0.025</timeConstantDown>
    <maxRotVelocity>1500</maxRotVelocity>
    <motorConstant>8.54858e-06</motorConstant>
    <momentConstant>0.06</momentConstant>
    <commandSubTopic>/gazebo/command/motor_speed</commandSubTopic>
    <motorNumber>5</motorNumber>
    <rotorDragCoefficient>0.000806428</rotorDragCoefficient>
    <rollingMomentCoefficient>1e-06</rollingMomentCoefficient>
    <motorSpeedPubTopic>/motor_speed/5</motorSpeedPubTopic>
    <rotorVelocitySlowdownSim>20</rotorVelocitySlowdownSim>
  </plugin>

  <plugin name='front_right_tip_motor_model' filename='libgazebo_motor_model.so'>
    <robotNamespace></robotNamespace>
    <jointName>motor_6_joint</jointName>
    <linkName>motor_6</linkName>
    <turningDirection>cw</turningDirection>
    <timeConstantUp>0.0125</timeConstantUp>
    <timeConstantDown>0.025</timeConstantDown>
    <maxRotVelocity>1500</maxRotVelocity>
    <motorConstant>8.54858e-06</motorConstant>
    <momentConstant>0.06</momentConstant>
    <commandSubTopic>/gazebo/command/motor_speed</commandSubTopic>
    <motorNumber>6</motorNumber>
    <rotorDragCoefficient>0.000806428</rotorDragCoefficient>
    <rollingMomentCoefficient>1e-06</rollingMomentCoefficient>
    <motorSpeedPubTopic>/motor_speed/6</motorSpeedPubTopic>
    <rotorVelocitySlowdownSim>20</rotorVelocitySlowdownSim>
  </plugin>

  <plugin name='back_right_tip_motor_model' filename='libgazebo_motor_model.so'>
    <robotNamespace></robotNamespace>
    <jointName>motor_8_joint</jointName>
    <linkName>motor_8</linkName>
    <turningDirection>ccw</turningDirection>
    <timeConstantUp>0.0125</timeConstantUp>
    <timeConstantDown>0.025</timeConstantDown>
    <maxRotVelocity>1500</maxRotVelocity>
    <motorConstant>8.54858e-06</motorConstant>
    <momentConstant>0.06</momentConstant>
    <commandSubTopic>/gazebo/command/motor_speed</commandSubTopic>
    <motorNumber>8</motorNumber>
    <rotorDragCoefficient>0.000806428</rotorDragCoefficient>
    <rollingMomentCoefficient>1e-06</rollingMomentCoefficient>
    <motorSpeedPubTopic>/motor_speed/8</motorSpeedPubTopic>
    <rotorVelocitySlowdownSim>20</rotorVelocitySlowdownSim>
  </plugin>

  <plugin name='back_left_tip_motor_model' filename='libgazebo_motor_model.so'>
    <robotNamespace></robotNamespace>
    <jointName>rotor_7_joint</jointName>
    <linkName>rotor_7</linkName>
    <turningDirection>cw</turningDirection>
    <timeConstantUp>0.0125</timeConstantUp>
    <timeConstantDown>0.025</timeConstantDown>
    <maxRotVelocity>1500</maxRotVelocity>
    <motorConstant>8.54858e-06</motorConstant>
    <momentConstant>0.06</momentConstant>
    <commandSubTopic>/gazebo/command/motor_speed</commandSubTopic>
    <motorNumber>7</motorNumber>
    <rotorDragCoefficient>0.000806428</rotorDragCoefficient>
    <rollingMomentCoefficient>1e-06</rollingMomentCoefficient>
    <motorSpeedPubTopic>/motor_speed/7</motorSpeedPubTopic>
    <rotorVelocitySlowdownSim>20</rotorVelocitySlowdownSim>
  </plugin>

  <plugin name='cruise_motor_model' filename='libgazebo_motor_model.so'>
    <robotNamespace></robotNamespace>
    <jointName>cruise_motor_joint</jointName>
    <linkName>cruise_motor</linkName>
    <turningDirection>ccw</turningDirection>
    <timeConstantUp>0.0125</timeConstantUp>
    <timeConstantDown>0.025</timeConstantDown>
    <maxRotVelocity>3500</maxRotVelocity>
    <motorConstant>8.54858e-06</motorConstant>
    <momentConstant>0.01</momentConstant>
    <commandSubTopic>/gazebo/command/motor_speed</commandSubTopic>
    <motorNumber>9</motorNumber>
    <rotorDragCoefficient>8.06428e-05</rotorDragCoefficient>
    <rollingMomentCoefficient>1e-06</rollingMomentCoefficient>
    <motorSpeedPubTopic>/motor_speed/9</motorSpeedPubTopic>
    <rotorVelocitySlowdownSim>20</rotorVelocitySlowdownSim>
  </plugin>

  <plugin name='left_wing' filename='libLiftDragPlugin.so'>
    <a0>0.05984281113</a0>
    <cla>4.752798721</cla>
    <cda>0.6417112299</cda>
    <cma>-1.8</cma>
    <alpha_stall>0.3391428111</alpha_stall>
    <cla_stall>-3.85</cla_stall>
    <cda_stall>-0.9233984055</cda_stall>
    <cma_stall>0</cma_stall>
    <cp>-0.05 0.3 0.05</cp>
    <area>0.50</area>
    <air_density>1.2041</air_density>
    <forward>1 0 0</forward>
    <upward>0 0 1</upward>
    <link_name>base_link</link_name>
    <control_joint_name>
      aileron_left_joint
    </control_joint_name>
    <control_joint_rad_to_cl>-1.0</control_joint_rad_to_cl>
  </plugin>

  <plugin name='right_wing' filename='libLiftDragPlugin.so'>
    <a0>0.05984281113</a0>
    <cla>4.752798721</cla>
    <cda>0.6417112299</cda>
    <cma>-1.8</cma>
    <alpha_stall>0.3391428111</alpha_stall>
    <cla_stall>-3.85</cla_stall>
    <cda_stall>-0.9233984055</cda_stall>
    <cma_stall>0</cma_stall>
    <cp>-0.05 -0.3 0.05</cp>
    <area>0.50</area>
    <air_density>1.2041</air_density>
    <forward>1 0 0</forward>
    <upward>0 0 1</upward>
    <link_name>base_link</link_name>
    <control_joint_name>
      aileron_right_joint
    </control_joint_name>
    <control_joint_rad_to_cl>-1.0</control_joint_rad_to_cl>
  </plugin>

  <plugin name="elevator" filename="libLiftDragPlugin.so">
    <a0>-0.2</a0>
    <cla>4.752798721</cla>
    <cda>0.6417112299</cda>
    <cma>-1.8</cma>
    <alpha_stall>0.3391428111</alpha_stall>
    <cla_stall>-3.85</cla_stall>
    <cda_stall>-0.9233984055</cda_stall>
    <cma_stall>0</cma_stall>
    <cp>-0.5 0 0</cp>
    <area>0.01</area>
    <air_density>1.2041</air_density>
    <forward>1 0 0</forward>
    <upward>0 0 1</upward>
    <link_name>base_link</link_name>
    <control_joint_name>
      elevator_joint
    </control_joint_name>
    <control_joint_rad_to_cl>-12.0</control_joint_rad_to_cl>
  </plugin>

  <plugin name="rudder" filename="libLiftDragPlugin.so">
    <a0>0.0</a0>
    <cla>4.752798721</cla>
    <cda>0.6417112299</cda>
    <cma>-1.8</cma>
    <alpha_stall>0.3391428111</alpha_stall>
    <cla_stall>-3.85</cla_stall>
    <cda_stall>-0.9233984055</cda_stall>
    <cma_stall>0</cma_stall>
    <cp>-0.5 0 0.05</cp>
    <area>0.02</area>
    <air_density>1.2041</air_density>
    <forward>1 0 0</forward>
    <upward>0 1 0</upward>
    <link_name>base_link</link_name>
  </plugin>

  <plugin name='gazebo_imu_plugin' filename='libgazebo_imu_plugin.so'>
    <robotNamespace></robotNamespace>
    <linkName>leap_vtol_mk3/imu_link</linkName>
    <imuTopic>/imu</imuTopic>
    <gyroscopeNoiseDensity>0.0003394</gyroscopeNoiseDensity>
    <gyroscopeRandomWalk>3.8785e-05</gyroscopeRandomWalk>
    <gyroscopeBiasCorrelationTime>1000.0</gyroscopeBiasCorrelationTime>
    <gyroscopeTurnOnBiasSigma>0.0087</gyroscopeTurnOnBiasSigma>
    <accelerometerNoiseDensity>0.004</accelerometerNoiseDensity>
    <accelerometerRandomWalk>0.006</accelerometerRandomWalk>
    <accelerometerBiasCorrelationTime>300.0</accelerometerBiasCorrelationTime>
    <accelerometerTurnOnBiasSigma>0.196</accelerometerTurnOnBiasSigma>
  </plugin>

  <plugin name='gps_plugin' filename='libgazebo_gps_plugin.so'>
      <robotNamespace></robotNamespace>
      <gpsNoise>true</gpsNoise>
  </plugin>

  <plugin name='magnetometer_plugin' filename='libgazebo_magnetometer_plugin.so'>
    <robotNamespace/>
    <pubRate>20</pubRate>
    <noiseDensity>0.0004</noiseDensity>
    <randomWalk>6.4e-06</randomWalk>
    <biasCorrelationTime>600</biasCorrelationTime>
    <magTopic>/mag</magTopic>
  </plugin>

  <plugin name='barometer_plugin' filename='libgazebo_barometer_plugin.so'>
    <robotNamespace/>
    <pubRate>10</pubRate>
    <baroTopic>/baro</baroTopic>
  </plugin>

  <plugin name='mavlink_interface' filename='libgazebo_mavlink_interface.so'>
    <robotNamespace></robotNamespace>
    <imuSubTopic>/imu</imuSubTopic>
    <gpsSubTopic>/gps</gpsSubTopic>
    <magSubTopic>/mag</magSubTopic>
    <baroSubTopic>/baro</baroSubTopic>
    <mavlink_addr>INADDR_ANY</mavlink_addr>
    <mavlink_udp_port>14560</mavlink_udp_port>
    <serialEnabled>true</serialEnabled>
    <serialDevice>/dev/ttyACM0</serialDevice>
    <baudRate>921600</baudRate>
    <qgc_addr>INADDR_ANY</qgc_addr>
    <qgc_udp_port>14550</qgc_udp_port>
    <sdk_addr>INADDR_ANY</sdk_addr>
    <sdk_udp_port>14540</sdk_udp_port>
    <hil_mode>true</hil_mode>
    <hil_state_level>false</hil_state_level>
    <enable_lockstep>true</enable_lockstep>
    <use_tcp>true</use_tcp>
    <motorSpeedCommandPubTopic>/gazebo/command/motor_speed</motorSpeedCommandPubTopic>
    <control_channels>
      <channel name="motor1">
        <input_index>0</input_index>
        <input_offset>0</input_offset>
        <input_scaling>1500</input_scaling>
        <zero_position_disarmed>0</zero_position_disarmed>
        <zero_position_armed>0</zero_position_armed>
        <joint_control_type>velocity</joint_control_type>
        <joint_name>motor_1_joint</joint_name>
      </channel>
      <channel name="motor2">
        <input_index>1</input_index>
        <input_offset>0</input_offset>
        <input_scaling>1500</input_scaling>
        <zero_position_disarmed>0</zero_position_disarmed>
        <zero_position_armed>0</zero_position_armed>
        <joint_control_type>velocity</joint_control_type>
        <joint_name>motor_2_joint</joint_name>
      </channel>
      <channel name="motor3">
        <input_index>2</input_index>
        <input_offset>0</input_offset>
        <input_scaling>1500</input_scaling>
        <zero_position_disarmed>0</zero_position_disarmed>
        <zero_position_armed>0</zero_position_armed>
        <joint_control_type>velocity</joint_control_type>
        <joint_name>motor_3_joint</joint_name>
      </channel>
      <channel name="motor4">
        <input_index>3</input_index>
        <input_offset>0</input_offset>
        <input_scaling>1500</input_scaling>
        <zero_position_disarmed>0</zero_position_disarmed>
        <zero_position_armed>0</zero_position_armed>
        <joint_control_type>velocity</joint_control_type>
        <joint_name>motor_4_joint</joint_name>
      </channel>
      <channel name="motor5">
        <input_index>4</input_index>
        <input_offset>0</input_offset>
        <input_scaling>5500</input_scaling>
        <zero_position_disarmed>0</zero_position_disarmed>
        <zero_position_armed>0</zero_position_armed>
        <joint_control_type>velocity</joint_control_type>
        <joint_name>motor_5_joint</joint_name>
      </channel>
      <channel name="motor6">
        <input_index>5</input_index>
        <input_offset>0</input_offset>
        <input_scaling>1500</input_scaling>
        <zero_position_disarmed>0</zero_position_disarmed>
        <zero_position_armed>0</zero_position_armed>
        <joint_control_type>velocity</joint_control_type>
        <joint_name>motor_6_joint</joint_name>
      </channel>
      <channel name="motor7">
        <input_index>6</input_index>
        <input_offset>0</input_offset>
        <input_scaling>1500</input_scaling>
        <zero_position_disarmed>0</zero_position_disarmed>
        <zero_position_armed>0</zero_position_armed>
        <joint_control_type>velocity</joint_control_type>
        <joint_name>motor_7_joint</joint_name>
      </channel>
      <channel name="motor8">
        <input_index>7</input_index>
        <input_offset>0</input_offset>
        <input_scaling>1500</input_scaling>
        <zero_position_disarmed>0</zero_position_disarmed>
        <zero_position_armed>0</zero_position_armed>
        <joint_control_type>velocity</joint_control_type>
        <joint_name>motor_8_joint</joint_name>
      </channel>
      <channel name="cruisemotor">
        <input_index>8</input_index>
        <input_offset>0</input_offset>
        <input_scaling>1500</input_scaling>
        <zero_position_disarmed>0</zero_position_disarmed>
        <zero_position_armed>0</zero_position_armed>
        <joint_control_type>velocity</joint_control_type>
        <joint_name>cruise_motor_joint</joint_name>
      </channel>
      <channel name="aileron_left">
        <input_index>9</input_index>
        <input_offset>0</input_offset>
        <input_scaling>1</input_scaling>
        <zero_position_disarmed>0</zero_position_disarmed>
        <zero_position_armed>0</zero_position_armed>
        <joint_control_type>position_kinematic</joint_control_type>
        <joint_name>aileron_left_joint</joint_name>
      </channel>
      <channel name="aileron_right">
        <input_index>10</input_index>
        <input_offset>0</input_offset>
        <input_scaling>1</input_scaling>
        <zero_position_disarmed>0</zero_position_disarmed>
        <zero_position_armed>0</zero_position_armed>
        <joint_control_type>position_kinematic</joint_control_type>
        <joint_name>aileron_right_joint</joint_name>
      </channel>
      <channel name="elevator">
        <input_index>11</input_index>
        <input_offset>0</input_offset>
        <input_scaling>1</input_scaling>
        <zero_position_disarmed>0</zero_position_disarmed>
        <zero_position_armed>0</zero_position_armed>
        <joint_control_type>position_kinematic</joint_control_type>
        <joint_name>elevator_joint</joint_name>
      </channel>
    </control_channels>
    <aileron_left_joint>
      aileron_left_joint
    </aileron_left_joint>
    <aileron_right_joint>
      aileron_right_joint
    </aileron_right_joint>
    <elevator_joint>
      elevator_joint
    </elevator_joint>
  </plugin>
</robot>
